Workbook

Sheet Description
B2: This dataset contains information collected by the US Census Service concerning housing in the area of Boston Massachusetts. It was obtained from the StatLib archive (http://lib.stat.cmu.edu/datasets/boston). The dataset has 506 cases.
B4: The data was originally published by Harrison, D. and Rubinfeld, D.L. `Hedonic prices and the demand for clean air', J. Environ. Economics & Management, vol.5, 81-102, 1978.
B6: There are 13 attributes in each case of the dataset. They are:
B8: CRIM per capita crime rate by town
B9: ZN proportion of residential land zoned for lots over 25,000 sq.ft.
B10: INDUS proportion of non-retail business acres per town.
B11: CHAS Charles River dummy variable (1 if tract bounds river; 0 otherwise)
B12: NOX nitric oxides concentration (parts per 10 million)
B13: RM average number of rooms per dwelling
B14: AGE proportion of owner-occupied units built prior to 1940
B15: DIS weighted distances to five Boston employment centres
B16: RAD index of accessibility to radial highways
... B20: MEDV Median value of owner-occupied homes in $1000

Sheet Boston_Housing
A1: RECORD ID | B1: CHAS | C1: CHAS Coded | D1: CRIM | E1: ZN | F1: INDUS | G1: NOX | H1: RM | I1: AGE | J1: DIS | K1: RAD | L1: TAX | M1: PTRATIO | N1: LSTAT | O1: MEDV
A2: 1 | B2: No | C2: =IF(B2="NO",0,1) -> 0 | D2: 0.00632 | E2: 18 | F2: 2.31 | G2: 0.538 | H2: 6.575 | I2: 65.2 | J2: 4.09 | K2: 1 | L2: 296 | M2: 15.3 | N2: 4.98 | O2: 24
A3: 2 | B3: No | C3: =IF(B3="NO",0,1) -> 0 | D3: 0.02731 | E3: 0 | F3: 7.07 | G3: 0.469 | H3: 6.421 | I3: 78.9 | J3: 4.9671 | K3: 2 | L3: 242 | M3: 17.8 | N3: 9.14 | O3: 21.6
A4: 3 | B4: No | C4: =IF(B4="NO",0,1) -> 0 | D4: 0.02729 | E4: 0 | F4: 7.07 | G4: 0.469 | H4: 7.185 | I4: 61.1 | J4: 4.9671 | K4: 2 | L4: 242 | M4: 17.8 | N4: 4.03 | O4: 34.7
A5: 4 | B5: No | C5: =IF(B5="NO",0,1) -> 0 | D5: 0.03237 | E5: 0 | F5: 2.18 | G5: 0.458 | H5: 6.998 | I5: 45.8 | J5: 6.0622 | K5: 3 | L5: 222 | M5: 18.7 | N5: 2.94 | O5: 33.4
A6: 5 | B6: No | C6: =IF(B6="NO",0,1) -> 0 | D6: 0.06905 | E6: 0 | F6: 2.18 | G6: 0.458 | H6: 7.147 | I6: 54.2 | J6: 6.0622 | K6: 3 | L6: 222 | M6: 18.7 | N6: 5.33 | O6: 36.2
A7: 6 | B7: No | C7: =IF(B7="NO",0,1) -> 0 | D7: 0.02985 | E7: 0 | F7: 2.18 | G7: 0.458 | H7: 6.43 | I7: 58.7 | J7: 6.0622 | K7: 3 | L7: 222 | M7: 18.7 | N7: 5.21 | O7: 28.7
A8: 7 | B8: No | C8: =IF(B8="NO",0,1) -> 0 | D8: 0.08829 | E8: 12.5 | F8: 7.87 | G8: 0.524 | H8: 6.012 | I8: 66.6 | J8: 5.5605 | K8: 5 | L8: 311 | M8: 15.2 | N8: 12.43 | O8: 22.9
A9: 8 | B9: No | C9: =IF(B9="NO",0,1) -> 0 | D9: 0.14455 | E9: 12.5 | F9: 7.87 | G9: 0.524 | H9: 6.172 | I9: 96.1 | J9: 5.9505 | K9: 5 | L9: 311 | M9: 15.2 | N9: 19.15 | O9: 27.1
A10: 9 | B10: No | C10: =IF(B10="NO",0,1) -> 0 | D10: 0.21124 | E10: 12.5 | F10: 7.87 | G10: 0.524 | H10: 5.631 | I10: 100 | J10: 6.0821 | K10: 5 | L10: 311 | M10: 15.2 | N10: 29.93 | O10: 16.5
A11: 10 | B11: No | C11: =IF(B11="NO",0,1) -> 0 | D11: 0.17004 | E11: 12.5 | F11: 7.87 | G11: 0.524 | H11: 6.004 | I11: 85.9 | J11: 6.5921 | K11: 5 | L11: 311 | M11: 15.2 | N11: 17.1 | O11: 18.9
A12: 11 | B12: No | C12: =IF(B12="NO",0,1) -> 0 | D12: 0.22489 | E12: 12.5 | F12: 7.87 | G12: 0.524 | H12: 6.377 | I12: 94.3 | J12: 6.3467 | K12: 5 | L12: 311 | M12: 15.2 | N12: 20.45 | O12: 15
A13: 12 | B13: No | C13: =IF(B13="NO",0,1) -> 0 | D13: 0.11747 | E13: 12.5 | F13: 7.87 | G13: 0.524 | H13: 6.009 | I13: 82.9 | J13: 6.2267 | K13: 5 | L13: 311 | M13: 15.2 | N13: 13.27 | O13: 18.9
... A507: 506 | B507: No | C507: =IF(B507="NO",0,1) -> 0 | D507: 0.04741 | E507: 0 | F507: 11.93 | G507: 0.573 | H507: 6.03 | I507: 80.8 | J507: 2.505 | K507: 1 | L507: 273 | M507: 21 | N507: 7.88 | O507: 11.9

Sheet Correlation

Sheet Scatter Plot

Sheet XLSTAT_20211102_141318_1_HID1
A1: 0 | B1: 24 | D1: 0.00632 | E1: 24 | G1: 18 | H1: 24 | J1: 2.31 | K1: 24 | M1: 0.538 | N1: 24 | P1: 6.575 | Q1: 24 | S1: 65.2 | T1: 24 | V1: 4.09 | W1: 24 | Y1: 1 | Z1: 24 | AB1: 296 | AC1: 24 | AE1: 15.3 | AF1: 24 | AH1: 4.98 | AI1: 24
A2: 0 | B2: 21.6 | D2: 0.02731 | E2: 21.6 | G2: 0 | H2: 21.6 | J2: 7.07 | K2: 21.6 | M2: 0.469 | N2: 21.6 | P2: 6.421 | Q2: 21.6 | S2: 78.9 | T2: 21.6 | V2: 4.9671 | W2: 21.6 | Y2: 2 | Z2: 21.6 | AB2: 242 | AC2: 21.6 | AE2: 17.8 | AF2: 21.6 | AH2: 9.14 | AI2: 21.6
A3: 0 | B3: 34.7 | D3: 0.02729 | E3: 34.7 | G3: 0 | H3: 34.7 | J3: 7.07 | K3: 34.7 | M3: 0.469 | N3: 34.7 | P3: 7.185 | Q3: 34.7 | S3: 61.1 | T3: 34.7 | V3: 4.9671 | W3: 34.7 | Y3: 2 | Z3: 34.7 | AB3: 242 | AC3: 34.7 | AE3: 17.8 | AF3: 34.7 | AH3: 4.03 | AI3: 34.7
A4: 0 | B4: 33.4 | D4: 0.03237 | E4: 33.4 | G4: 0 | H4: 33.4 | J4: 2.18 | K4: 33.4 | M4: 0.458 | N4: 33.4 | P4: 6.998 | Q4: 33.4 | S4: 45.8 | T4: 33.4 | V4: 6.0622 | W4: 33.4 | Y4: 3 | Z4: 33.4 | AB4: 222 | AC4: 33.4 | AE4: 18.7 | AF4: 33.4 | AH4: 2.94 | AI4: 33.4
A5: 0 | B5: 36.2 | D5: 0.06905 | E5: 36.2 | G5: 0 | H5: 36.2 | J5: 2.18 | K5: 36.2 | M5: 0.458 | N5: 36.2 | P5: 7.147 | Q5: 36.2 | S5: 54.2 | T5: 36.2 | V5: 6.0622 | W5: 36.2 | Y5: 3 | Z5: 36.2 | AB5: 222 | AC5: 36.2 | AE5: 18.7 | AF5: 36.2 | AH5: 5.33 | AI5: 36.2
A6: 0 | B6: 28.7 | D6: 0.02985 | E6: 28.7 | G6: 0 | H6: 28.7 | J6: 2.18 | K6: 28.7 | M6: 0.458 | N6: 28.7 | P6: 6.43 | Q6: 28.7 | S6: 58.7 | T6: 28.7 | V6: 6.0622 | W6: 28.7 | Y6: 3 | Z6: 28.7 | AB6: 222 | AC6: 28.7 | AE6: 18.7 | AF6: 28.7 | AH6: 5.21 | AI6: 28.7
A7: 0 | B7: 22.9 | D7: 0.08829 | E7: 22.9 | G7: 12.5 | H7: 22.9 | J7: 7.87 | K7: 22.9 | M7: 0.524 | N7: 22.9 | P7: 6.012 | Q7: 22.9 | S7: 66.6 | T7: 22.9 | V7: 5.5605 | W7: 22.9 | Y7: 5 | Z7: 22.9 | AB7: 311 | AC7: 22.9 | AE7: 15.2 | AF7: 22.9 | AH7: 12.43 | AI7: 22.9
A8: 0 | B8: 27.1 | D8: 0.14455 | E8: 27.1 | G8: 12.5 | H8: 27.1 | J8: 7.87 | K8: 27.1 | M8: 0.524 | N8: 27.1 | P8: 6.172 | Q8: 27.1 | S8: 96.1 | T8: 27.1 | V8: 5.9505 | W8: 27.1 | Y8: 5 | Z8: 27.1 | AB8: 311 | AC8: 27.1 | AE8: 15.2 | AF8: 27.1 | AH8: 19.15 | AI8: 27.1
A9: 0 | B9: 16.5 | D9: 0.21124 | E9: 16.5 | G9: 12.5 | H9: 16.5 | J9: 7.87 | K9: 16.5 | M9: 0.524 | N9: 16.5 | P9: 5.631 | Q9: 16.5 | S9: 100 | T9: 16.5 | V9: 6.0821 | W9: 16.5 | Y9: 5 | Z9: 16.5 | AB9: 311 | AC9: 16.5 | AE9: 15.2 | AF9: 16.5 | AH9: 29.93 | AI9: 16.5
A10: 0 | B10: 18.9 | D10: 0.17004 | E10: 18.9 | G10: 12.5 | H10: 18.9 | J10: 7.87 | K10: 18.9 | M10: 0.524 | N10: 18.9 | P10: 6.004 | Q10: 18.9 | S10: 85.9 | T10: 18.9 | V10: 6.5921 | W10: 18.9 | Y10: 5 | Z10: 18.9 | AB10: 311 | AC10: 18.9 | AE10: 15.2 | AF10: 18.9 | AH10: 17.1 | AI10: 18.9
A11: 0 | B11: 15 | D11: 0.22489 | E11: 15 | G11: 12.5 | H11: 15 | J11: 7.87 | K11: 15 | M11: 0.524 | N11: 15 | P11: 6.377 | Q11: 15 | S11: 94.3 | T11: 15 | V11: 6.3467 | W11: 15 | Y11: 5 | Z11: 15 | AB11: 311 | AC11: 15 | AE11: 15.2 | AF11: 15 | AH11: 20.45 | AI11: 15
A12: 0 | B12: 18.9 | D12: 0.11747 | E12: 18.9 | G12: 12.5 | H12: 18.9 | J12: 7.87 | K12: 18.9 | M12: 0.524 | N12: 18.9 | P12: 6.009 | Q12: 18.9 | S12: 82.9 | T12: 18.9 | V12: 6.2267 | W12: 18.9 | Y12: 5 | Z12: 18.9 | AB12: 311 | AC12: 18.9 | AE12: 15.2 | AF12: 18.9 | AH12: 13.27 | AI12: 18.9
... A506: 0 | B506: 11.9 | D506: 0.04741 | E506: 11.9 | G506: 0 | H506: 11.9 | J506: 11.93 | K506: 11.9 | M506: 0.573 | N506: 11.9 | P506: 6.03 | Q506: 11.9 | S506: 80.8 | T506: 11.9 | V506: 2.505 | W506: 11.9 | Y506: 1 | Z506: 11.9 | AB506: 273 | AC506: 11.9 | AE506: 21 | AF506: 11.9 | AH506: 7.88 | AI506: 11.9

Sheet XLSTAT_20211102_141318_1_HID
A1: 0 | B1: 24 | D1: 0.00632 | E1: 24 | G1: 18 | H1: 24 | J1: 2.31 | K1: 24 | M1: 0.538 | N1: 24 | P1: 6.575 | Q1: 24 | S1: 65.2 | T1: 24 | V1: 4.09 | W1: 24 | Y1: 1 | Z1: 24 | AB1: 296 | AC1: 24 | AE1: 15.3 | AF1: 24 | AH1: 4.98 | AI1: 24
A2: 0 | B2: 21.6 | D2: 0.02731 | E2: 21.6 | G2: 0 | H2: 21.6 | J2: 7.07 | K2: 21.6 | M2: 0.469 | N2: 21.6 | P2: 6.421 | Q2: 21.6 | S2: 78.9 | T2: 21.6 | V2: 4.9671 | W2: 21.6 | Y2: 2 | Z2: 21.6 | AB2: 242 | AC2: 21.6 | AE2: 17.8 | AF2: 21.6 | AH2: 9.14 | AI2: 21.6
A3: 0 | B3: 34.7 | D3: 0.02729 | E3: 34.7 | G3: 0 | H3: 34.7 | J3: 7.07 | K3: 34.7 | M3: 0.469 | N3: 34.7 | P3: 7.185 | Q3: 34.7 | S3: 61.1 | T3: 34.7 | V3: 4.9671 | W3: 34.7 | Y3: 2 | Z3: 34.7 | AB3: 242 | AC3: 34.7 | AE3: 17.8 | AF3: 34.7 | AH3: 4.03 | AI3: 34.7
A4: 0 | B4: 33.4 | D4: 0.03237 | E4: 33.4 | G4: 0 | H4: 33.4 | J4: 2.18 | K4: 33.4 | M4: 0.458 | N4: 33.4 | P4: 6.998 | Q4: 33.4 | S4: 45.8 | T4: 33.4 | V4: 6.0622 | W4: 33.4 | Y4: 3 | Z4: 33.4 | AB4: 222 | AC4: 33.4 | AE4: 18.7 | AF4: 33.4 | AH4: 2.94 | AI4: 33.4
A5: 0 | B5: 36.2 | D5: 0.06905 | E5: 36.2 | G5: 0 | H5: 36.2 | J5: 2.18 | K5: 36.2 | M5: 0.458 | N5: 36.2 | P5: 7.147 | Q5: 36.2 | S5: 54.2 | T5: 36.2 | V5: 6.0622 | W5: 36.2 | Y5: 3 | Z5: 36.2 | AB5: 222 | AC5: 36.2 | AE5: 18.7 | AF5: 36.2 | AH5: 5.33 | AI5: 36.2
A6: 0 | B6: 28.7 | D6: 0.02985 | E6: 28.7 | G6: 0 | H6: 28.7 | J6: 2.18 | K6: 28.7 | M6: 0.458 | N6: 28.7 | P6: 6.43 | Q6: 28.7 | S6: 58.7 | T6: 28.7 | V6: 6.0622 | W6: 28.7 | Y6: 3 | Z6: 28.7 | AB6: 222 | AC6: 28.7 | AE6: 18.7 | AF6: 28.7 | AH6: 5.21 | AI6: 28.7
A7: 0 | B7: 22.9 | D7: 0.08829 | E7: 22.9 | G7: 12.5 | H7: 22.9 | J7: 7.87 | K7: 22.9 | M7: 0.524 | N7: 22.9 | P7: 6.012 | Q7: 22.9 | S7: 66.6 | T7: 22.9 | V7: 5.5605 | W7: 22.9 | Y7: 5 | Z7: 22.9 | AB7: 311 | AC7: 22.9 | AE7: 15.2 | AF7: 22.9 | AH7: 12.43 | AI7: 22.9
A8: 0 | B8: 27.1 | D8: 0.14455 | E8: 27.1 | G8: 12.5 | H8: 27.1 | J8: 7.87 | K8: 27.1 | M8: 0.524 | N8: 27.1 | P8: 6.172 | Q8: 27.1 | S8: 96.1 | T8: 27.1 | V8: 5.9505 | W8: 27.1 | Y8: 5 | Z8: 27.1 | AB8: 311 | AC8: 27.1 | AE8: 15.2 | AF8: 27.1 | AH8: 19.15 | AI8: 27.1
A9: 0 | B9: 16.5 | D9: 0.21124 | E9: 16.5 | G9: 12.5 | H9: 16.5 | J9: 7.87 | K9: 16.5 | M9: 0.524 | N9: 16.5 | P9: 5.631 | Q9: 16.5 | S9: 100 | T9: 16.5 | V9: 6.0821 | W9: 16.5 | Y9: 5 | Z9: 16.5 | AB9: 311 | AC9: 16.5 | AE9: 15.2 | AF9: 16.5 | AH9: 29.93 | AI9: 16.5
A10: 0 | B10: 18.9 | D10: 0.17004 | E10: 18.9 | G10: 12.5 | H10: 18.9 | J10: 7.87 | K10: 18.9 | M10: 0.524 | N10: 18.9 | P10: 6.004 | Q10: 18.9 | S10: 85.9 | T10: 18.9 | V10: 6.5921 | W10: 18.9 | Y10: 5 | Z10: 18.9 | AB10: 311 | AC10: 18.9 | AE10: 15.2 | AF10: 18.9 | AH10: 17.1 | AI10: 18.9
A11: 0 | B11: 15 | D11: 0.22489 | E11: 15 | G11: 12.5 | H11: 15 | J11: 7.87 | K11: 15 | M11: 0.524 | N11: 15 | P11: 6.377 | Q11: 15 | S11: 94.3 | T11: 15 | V11: 6.3467 | W11: 15 | Y11: 5 | Z11: 15 | AB11: 311 | AC11: 15 | AE11: 15.2 | AF11: 15 | AH11: 20.45 | AI11: 15
A12: 0 | B12: 18.9 | D12: 0.11747 | E12: 18.9 | G12: 12.5 | H12: 18.9 | J12: 7.87 | K12: 18.9 | M12: 0.524 | N12: 18.9 | P12: 6.009 | Q12: 18.9 | S12: 82.9 | T12: 18.9 | V12: 6.2267 | W12: 18.9 | Y12: 5 | Z12: 18.9 | AB12: 311 | AC12: 18.9 | AE12: 15.2 | AF12: 18.9 | AH12: 13.27 | AI12: 18.9
... A506: 0 | B506: 11.9 | D506: 0.04741 | E506: 11.9 | G506: 0 | H506: 11.9 | J506: 11.93 | K506: 11.9 | M506: 0.573 | N506: 11.9 | P506: 6.03 | Q506: 11.9 | S506: 80.8 | T506: 11.9 | V506: 2.505 | W506: 11.9 | Y506: 1 | Z506: 11.9 | AB506: 273 | AC506: 11.9 | AE506: 21 | AF506: 11.9 | AH506: 7.88 | AI506: 11.9

Sheet SCA_HID
A1: 0.00632 | B1: 24 | D1: 18 | E1: 24 | G1: 2.31 | H1: 24 | J1: 0.538 | K1: 24 | M1: 6.575 | N1: 24 | P1: 65.2 | Q1: 24 | S1: 4.09 | T1: 24 | V1: 1 | W1: 24 | Y1: 296 | Z1: 24 | AB1: 15.3 | AC1: 24 | AE1: 4.98 | AF1: 24
A2: 0.02731 | B2: 21.6 | D2: 0 | E2: 21.6 | G2: 7.07 | H2: 21.6 | J2: 0.469 | K2: 21.6 | M2: 6.421 | N2: 21.6 | P2: 78.9 | Q2: 21.6 | S2: 4.9671 | T2: 21.6 | V2: 2 | W2: 21.6 | Y2: 242 | Z2: 21.6 | AB2: 17.8 | AC2: 21.6 | AE2: 9.14 | AF2: 21.6
A3: 0.02729 | B3: 34.7 | D3: 0 | E3: 34.7 | G3: 7.07 | H3: 34.7 | J3: 0.469 | K3: 34.7 | M3: 7.185 | N3: 34.7 | P3: 61.1 | Q3: 34.7 | S3: 4.9671 | T3: 34.7 | V3: 2 | W3: 34.7 | Y3: 242 | Z3: 34.7 | AB3: 17.8 | AC3: 34.7 | AE3: 4.03 | AF3: 34.7
A4: 0.03237 | B4: 33.4 | D4: 0 | E4: 33.4 | G4: 2.18 | H4: 33.4 | J4: 0.458 | K4: 33.4 | M4: 6.998 | N4: 33.4 | P4: 45.8 | Q4: 33.4 | S4: 6.0622 | T4: 33.4 | V4: 3 | W4: 33.4 | Y4: 222 | Z4: 33.4 | AB4: 18.7 | AC4: 33.4 | AE4: 2.94 | AF4: 33.4
A5: 0.06905 | B5: 36.2 | D5: 0 | E5: 36.2 | G5: 2.18 | H5: 36.2 | J5: 0.458 | K5: 36.2 | M5: 7.147 | N5: 36.2 | P5: 54.2 | Q5: 36.2 | S5: 6.0622 | T5: 36.2 | V5: 3 | W5: 36.2 | Y5: 222 | Z5: 36.2 | AB5: 18.7 | AC5: 36.2 | AE5: 5.33 | AF5: 36.2
A6: 0.02985 | B6: 28.7 | D6: 0 | E6: 28.7 | G6: 2.18 | H6: 28.7 | J6: 0.458 | K6: 28.7 | M6: 6.43 | N6: 28.7 | P6: 58.7 | Q6: 28.7 | S6: 6.0622 | T6: 28.7 | V6: 3 | W6: 28.7 | Y6: 222 | Z6: 28.7 | AB6: 18.7 | AC6: 28.7 | AE6: 5.21 | AF6: 28.7
A7: 0.08829 | B7: 22.9 | D7: 12.5 | E7: 22.9 | G7: 7.87 | H7: 22.9 | J7: 0.524 | K7: 22.9 | M7: 6.012 | N7: 22.9 | P7: 66.6 | Q7: 22.9 | S7: 5.5605 | T7: 22.9 | V7: 5 | W7: 22.9 | Y7: 311 | Z7: 22.9 | AB7: 15.2 | AC7: 22.9 | AE7: 12.43 | AF7: 22.9
A8: 0.14455 | B8: 27.1 | D8: 12.5 | E8: 27.1 | G8: 7.87 | H8: 27.1 | J8: 0.524 | K8: 27.1 | M8: 6.172 | N8: 27.1 | P8: 96.1 | Q8: 27.1 | S8: 5.9505 | T8: 27.1 | V8: 5 | W8: 27.1 | Y8: 311 | Z8: 27.1 | AB8: 15.2 | AC8: 27.1 | AE8: 19.15 | AF8: 27.1
A9: 0.21124 | B9: 16.5 | D9: 12.5 | E9: 16.5 | G9: 7.87 | H9: 16.5 | J9: 0.524 | K9: 16.5 | M9: 5.631 | N9: 16.5 | P9: 100 | Q9: 16.5 | S9: 6.0821 | T9: 16.5 | V9: 5 | W9: 16.5 | Y9: 311 | Z9: 16.5 | AB9: 15.2 | AC9: 16.5 | AE9: 29.93 | AF9: 16.5
A10: 0.17004 | B10: 18.9 | D10: 12.5 | E10: 18.9 | G10: 7.87 | H10: 18.9 | J10: 0.524 | K10: 18.9 | M10: 6.004 | N10: 18.9 | P10: 85.9 | Q10: 18.9 | S10: 6.5921 | T10: 18.9 | V10: 5 | W10: 18.9 | Y10: 311 | Z10: 18.9 | AB10: 15.2 | AC10: 18.9 | AE10: 17.1 | AF10: 18.9
A11: 0.22489 | B11: 15 | D11: 12.5 | E11: 15 | G11: 7.87 | H11: 15 | J11: 0.524 | K11: 15 | M11: 6.377 | N11: 15 | P11: 94.3 | Q11: 15 | S11: 6.3467 | T11: 15 | V11: 5 | W11: 15 | Y11: 311 | Z11: 15 | AB11: 15.2 | AC11: 15 | AE11: 20.45 | AF11: 15
A12: 0.11747 | B12: 18.9 | D12: 12.5 | E12: 18.9 | G12: 7.87 | H12: 18.9 | J12: 0.524 | K12: 18.9 | M12: 6.009 | N12: 18.9 | P12: 82.9 | Q12: 18.9 | S12: 6.2267 | T12: 18.9 | V12: 5 | W12: 18.9 | Y12: 311 | Z12: 18.9 | AB12: 15.2 | AC12: 18.9 | AE12: 13.27 | AF12: 18.9
... A506: 0.04741 | B506: 11.9 | D506: 0 | E506: 11.9 | G506: 11.93 | H506: 11.9 | J506: 0.573 | K506: 11.9 | M506: 6.03 | N506: 11.9 | P506: 80.8 | Q506: 11.9 | S506: 2.505 | T506: 11.9 | V506: 1 | W506: 11.9 | Y506: 273 | Z506: 11.9 | AB506: 21 | AC506: 11.9 | AE506: 7.88 | AF506: 11.9

Sheet SCA_HID1
A1: 0.00632 | B1: 24 | D1: 18 | E1: 24 | G1: 2.31 | H1: 24 | J1: 0 | K1: 24 | M1: 0.538 | N1: 24 | P1: 6.575 | Q1: 24 | S1: 65.2 | T1: 24 | V1: 4.09 | W1: 24 | Y1: 1 | Z1: 24 | AB1: 296 | AC1: 24 | AE1: 15.3 | AF1: 24 | AH1: 4.98 | AI1: 24
A2: 0.02731 | B2: 21.6 | D2: 0 | E2: 21.6 | G2: 7.07 | H2: 21.6 | J2: 0 | K2: 21.6 | M2: 0.469 | N2: 21.6 | P2: 6.421 | Q2: 21.6 | S2: 78.9 | T2: 21.6 | V2: 4.9671 | W2: 21.6 | Y2: 2 | Z2: 21.6 | AB2: 242 | AC2: 21.6 | AE2: 17.8 | AF2: 21.6 | AH2: 9.14 | AI2: 21.6
A3: 0.02729 | B3: 34.7 | D3: 0 | E3: 34.7 | G3: 7.07 | H3: 34.7 | J3: 0 | K3: 34.7 | M3: 0.469 | N3: 34.7 | P3: 7.185 | Q3: 34.7 | S3: 61.1 | T3: 34.7 | V3: 4.9671 | W3: 34.7 | Y3: 2 | Z3: 34.7 | AB3: 242 | AC3: 34.7 | AE3: 17.8 | AF3: 34.7 | AH3: 4.03 | AI3: 34.7
A4: 0.03237 | B4: 33.4 | D4: 0 | E4: 33.4 | G4: 2.18 | H4: 33.4 | J4: 0 | K4: 33.4 | M4: 0.458 | N4: 33.4 | P4: 6.998 | Q4: 33.4 | S4: 45.8 | T4: 33.4 | V4: 6.0622 | W4: 33.4 | Y4: 3 | Z4: 33.4 | AB4: 222 | AC4: 33.4 | AE4: 18.7 | AF4: 33.4 | AH4: 2.94 | AI4: 33.4
A5: 0.06905 | B5: 36.2 | D5: 0 | E5: 36.2 | G5: 2.18 | H5: 36.2 | J5: 0 | K5: 36.2 | M5: 0.458 | N5: 36.2 | P5: 7.147 | Q5: 36.2 | S5: 54.2 | T5: 36.2 | V5: 6.0622 | W5: 36.2 | Y5: 3 | Z5: 36.2 | AB5: 222 | AC5: 36.2 | AE5: 18.7 | AF5: 36.2 | AH5: 5.33 | AI5: 36.2
A6: 0.02985 | B6: 28.7 | D6: 0 | E6: 28.7 | G6: 2.18 | H6: 28.7 | J6: 0 | K6: 28.7 | M6: 0.458 | N6: 28.7 | P6: 6.43 | Q6: 28.7 | S6: 58.7 | T6: 28.7 | V6: 6.0622 | W6: 28.7 | Y6: 3 | Z6: 28.7 | AB6: 222 | AC6: 28.7 | AE6: 18.7 | AF6: 28.7 | AH6: 5.21 | AI6: 28.7
A7: 0.08829 | B7: 22.9 | D7: 12.5 | E7: 22.9 | G7: 7.87 | H7: 22.9 | J7: 0 | K7: 22.9 | M7: 0.524 | N7: 22.9 | P7: 6.012 | Q7: 22.9 | S7: 66.6 | T7: 22.9 | V7: 5.5605 | W7: 22.9 | Y7: 5 | Z7: 22.9 | AB7: 311 | AC7: 22.9 | AE7: 15.2 | AF7: 22.9 | AH7: 12.43 | AI7: 22.9
A8: 0.14455 | B8: 27.1 | D8: 12.5 | E8: 27.1 | G8: 7.87 | H8: 27.1 | J8: 0 | K8: 27.1 | M8: 0.524 | N8: 27.1 | P8: 6.172 | Q8: 27.1 | S8: 96.1 | T8: 27.1 | V8: 5.9505 | W8: 27.1 | Y8: 5 | Z8: 27.1 | AB8: 311 | AC8: 27.1 | AE8: 15.2 | AF8: 27.1 | AH8: 19.15 | AI8: 27.1
A9: 0.21124 | B9: 16.5 | D9: 12.5 | E9: 16.5 | G9: 7.87 | H9: 16.5 | J9: 0 | K9: 16.5 | M9: 0.524 | N9: 16.5 | P9: 5.631 | Q9: 16.5 | S9: 100 | T9: 16.5 | V9: 6.0821 | W9: 16.5 | Y9: 5 | Z9: 16.5 | AB9: 311 | AC9: 16.5 | AE9: 15.2 | AF9: 16.5 | AH9: 29.93 | AI9: 16.5
A10: 0.17004 | B10: 18.9 | D10: 12.5 | E10: 18.9 | G10: 7.87 | H10: 18.9 | J10: 0 | K10: 18.9 | M10: 0.524 | N10: 18.9 | P10: 6.004 | Q10: 18.9 | S10: 85.9 | T10: 18.9 | V10: 6.5921 | W10: 18.9 | Y10: 5 | Z10: 18.9 | AB10: 311 | AC10: 18.9 | AE10: 15.2 | AF10: 18.9 | AH10: 17.1 | AI10: 18.9
A11: 0.22489 | B11: 15 | D11: 12.5 | E11: 15 | G11: 7.87 | H11: 15 | J11: 0 | K11: 15 | M11: 0.524 | N11: 15 | P11: 6.377 | Q11: 15 | S11: 94.3 | T11: 15 | V11: 6.3467 | W11: 15 | Y11: 5 | Z11: 15 | AB11: 311 | AC11: 15 | AE11: 15.2 | AF11: 15 | AH11: 20.45 | AI11: 15
A12: 0.11747 | B12: 18.9 | D12: 12.5 | E12: 18.9 | G12: 7.87 | H12: 18.9 | J12: 0 | K12: 18.9 | M12: 0.524 | N12: 18.9 | P12: 6.009 | Q12: 18.9 | S12: 82.9 | T12: 18.9 | V12: 6.2267 | W12: 18.9 | Y12: 5 | Z12: 18.9 | AB12: 311 | AC12: 18.9 | AE12: 15.2 | AF12: 18.9 | AH12: 13.27 | AI12: 18.9
... A506: 0.04741 | B506: 11.9 | D506: 0 | E506: 11.9 | G506: 11.93 | H506: 11.9 | J506: 0 | K506: 11.9 | M506: 0.573 | N506: 11.9 | P506: 6.03 | Q506: 11.9 | S506: 80.8 | T506: 11.9 | V506: 2.505 | W506: 11.9 | Y506: 1 | Z506: 11.9 | AB506: 273 | AC506: 11.9 | AE506: 21 | AF506: 11.9 | AH506: 7.88 | AI506: 11.9

Sheet SCA1_HID
A1: 0.00632 | B1: 24 | D1: 18 | E1: 24 | G1: 2.31 | H1: 24 | J1: 0 | K1: 24 | M1: 0.538 | N1: 24 | P1: 6.575 | Q1: 24 | S1: 65.2 | T1: 24 | V1: 4.09 | W1: 24 | Y1: 1 | Z1: 24 | AB1: 296 | AC1: 24 | AE1: 15.3 | AF1: 24 | AH1: 4.98 | AI1: 24
A2: 0.02731 | B2: 21.6 | D2: 0 | E2: 21.6 | G2: 7.07 | H2: 21.6 | J2: 0 | K2: 21.6 | M2: 0.469 | N2: 21.6 | P2: 6.421 | Q2: 21.6 | S2: 78.9 | T2: 21.6 | V2: 4.9671 | W2: 21.6 | Y2: 2 | Z2: 21.6 | AB2: 242 | AC2: 21.6 | AE2: 17.8 | AF2: 21.6 | AH2: 9.14 | AI2: 21.6
A3: 0.02729 | B3: 34.7 | D3: 0 | E3: 34.7 | G3: 7.07 | H3: 34.7 | J3: 0 | K3: 34.7 | M3: 0.469 | N3: 34.7 | P3: 7.185 | Q3: 34.7 | S3: 61.1 | T3: 34.7 | V3: 4.9671 | W3: 34.7 | Y3: 2 | Z3: 34.7 | AB3: 242 | AC3: 34.7 | AE3: 17.8 | AF3: 34.7 | AH3: 4.03 | AI3: 34.7
A4: 0.03237 | B4: 33.4 | D4: 0 | E4: 33.4 | G4: 2.18 | H4: 33.4 | J4: 0 | K4: 33.4 | M4: 0.458 | N4: 33.4 | P4: 6.998 | Q4: 33.4 | S4: 45.8 | T4: 33.4 | V4: 6.0622 | W4: 33.4 | Y4: 3 | Z4: 33.4 | AB4: 222 | AC4: 33.4 | AE4: 18.7 | AF4: 33.4 | AH4: 2.94 | AI4: 33.4
A5: 0.06905 | B5: 36.2 | D5: 0 | E5: 36.2 | G5: 2.18 | H5: 36.2 | J5: 0 | K5: 36.2 | M5: 0.458 | N5: 36.2 | P5: 7.147 | Q5: 36.2 | S5: 54.2 | T5: 36.2 | V5: 6.0622 | W5: 36.2 | Y5: 3 | Z5: 36.2 | AB5: 222 | AC5: 36.2 | AE5: 18.7 | AF5: 36.2 | AH5: 5.33 | AI5: 36.2
A6: 0.02985 | B6: 28.7 | D6: 0 | E6: 28.7 | G6: 2.18 | H6: 28.7 | J6: 0 | K6: 28.7 | M6: 0.458 | N6: 28.7 | P6: 6.43 | Q6: 28.7 | S6: 58.7 | T6: 28.7 | V6: 6.0622 | W6: 28.7 | Y6: 3 | Z6: 28.7 | AB6: 222 | AC6: 28.7 | AE6: 18.7 | AF6: 28.7 | AH6: 5.21 | AI6: 28.7
A7: 0.08829 | B7: 22.9 | D7: 12.5 | E7: 22.9 | G7: 7.87 | H7: 22.9 | J7: 0 | K7: 22.9 | M7: 0.524 | N7: 22.9 | P7: 6.012 | Q7: 22.9 | S7: 66.6 | T7: 22.9 | V7: 5.5605 | W7: 22.9 | Y7: 5 | Z7: 22.9 | AB7: 311 | AC7: 22.9 | AE7: 15.2 | AF7: 22.9 | AH7: 12.43 | AI7: 22.9
A8: 0.14455 | B8: 27.1 | D8: 12.5 | E8: 27.1 | G8: 7.87 | H8: 27.1 | J8: 0 | K8: 27.1 | M8: 0.524 | N8: 27.1 | P8: 6.172 | Q8: 27.1 | S8: 96.1 | T8: 27.1 | V8: 5.9505 | W8: 27.1 | Y8: 5 | Z8: 27.1 | AB8: 311 | AC8: 27.1 | AE8: 15.2 | AF8: 27.1 | AH8: 19.15 | AI8: 27.1
A9: 0.21124 | B9: 16.5 | D9: 12.5 | E9: 16.5 | G9: 7.87 | H9: 16.5 | J9: 0 | K9: 16.5 | M9: 0.524 | N9: 16.5 | P9: 5.631 | Q9: 16.5 | S9: 100 | T9: 16.5 | V9: 6.0821 | W9: 16.5 | Y9: 5 | Z9: 16.5 | AB9: 311 | AC9: 16.5 | AE9: 15.2 | AF9: 16.5 | AH9: 29.93 | AI9: 16.5
A10: 0.17004 | B10: 18.9 | D10: 12.5 | E10: 18.9 | G10: 7.87 | H10: 18.9 | J10: 0 | K10: 18.9 | M10: 0.524 | N10: 18.9 | P10: 6.004 | Q10: 18.9 | S10: 85.9 | T10: 18.9 | V10: 6.5921 | W10: 18.9 | Y10: 5 | Z10: 18.9 | AB10: 311 | AC10: 18.9 | AE10: 15.2 | AF10: 18.9 | AH10: 17.1 | AI10: 18.9
A11: 0.22489 | B11: 15 | D11: 12.5 | E11: 15 | G11: 7.87 | H11: 15 | J11: 0 | K11: 15 | M11: 0.524 | N11: 15 | P11: 6.377 | Q11: 15 | S11: 94.3 | T11: 15 | V11: 6.3467 | W11: 15 | Y11: 5 | Z11: 15 | AB11: 311 | AC11: 15 | AE11: 15.2 | AF11: 15 | AH11: 20.45 | AI11: 15
A12: 0.11747 | B12: 18.9 | D12: 12.5 | E12: 18.9 | G12: 7.87 | H12: 18.9 | J12: 0 | K12: 18.9 | M12: 0.524 | N12: 18.9 | P12: 6.009 | Q12: 18.9 | S12: 82.9 | T12: 18.9 | V12: 6.2267 | W12: 18.9 | Y12: 5 | Z12: 18.9 | AB12: 311 | AC12: 18.9 | AE12: 15.2 | AF12: 18.9 | AH12: 13.27 | AI12: 18.9
... A506: 0.04741 | B506: 11.9 | D506: 0 | E506: 11.9 | G506: 11.93 | H506: 11.9 | J506: 0 | K506: 11.9 | M506: 0.573 | N506: 11.9 | P506: 6.03 | Q506: 11.9 | S506: 80.8 | T506: 11.9 | V506: 2.505 | W506: 11.9 | Y506: 1 | Z506: 11.9 | AB506: 273 | AC506: 11.9 | AE506: 21 | AF506: 11.9 | AH506: 7.88 | AI506: 11.9

Sheet SCA_HID2
A1: 0.00632 | B1: 24 | D1: 18 | E1: 24 | G1: 2.31 | H1: 24 | J1: 0 | K1: 24 | M1: 0.538 | N1: 24 | P1: 6.575 | Q1: 24 | S1: 65.2 | T1: 24 | V1: 4.09 | W1: 24 | Y1: 1 | Z1: 24 | AB1: 296 | AC1: 24 | AE1: 15.3 | AF1: 24 | AH1: 4.98 | AI1: 24
A2: 0.02731 | B2: 21.6 | D2: 0 | E2: 21.6 | G2: 7.07 | H2: 21.6 | J2: 0 | K2: 21.6 | M2: 0.469 | N2: 21.6 | P2: 6.421 | Q2: 21.6 | S2: 78.9 | T2: 21.6 | V2: 4.9671 | W2: 21.6 | Y2: 2 | Z2: 21.6 | AB2: 242 | AC2: 21.6 | AE2: 17.8 | AF2: 21.6 | AH2: 9.14 | AI2: 21.6
A3: 0.02729 | B3: 34.7 | D3: 0 | E3: 34.7 | G3: 7.07 | H3: 34.7 | J3: 0 | K3: 34.7 | M3: 0.469 | N3: 34.7 | P3: 7.185 | Q3: 34.7 | S3: 61.1 | T3: 34.7 | V3: 4.9671 | W3: 34.7 | Y3: 2 | Z3: 34.7 | AB3: 242 | AC3: 34.7 | AE3: 17.8 | AF3: 34.7 | AH3: 4.03 | AI3: 34.7
A4: 0.03237 | B4: 33.4 | D4: 0 | E4: 33.4 | G4: 2.18 | H4: 33.4 | J4: 0 | K4: 33.4 | M4: 0.458 | N4: 33.4 | P4: 6.998 | Q4: 33.4 | S4: 45.8 | T4: 33.4 | V4: 6.0622 | W4: 33.4 | Y4: 3 | Z4: 33.4 | AB4: 222 | AC4: 33.4 | AE4: 18.7 | AF4: 33.4 | AH4: 2.94 | AI4: 33.4
A5: 0.06905 | B5: 36.2 | D5: 0 | E5: 36.2 | G5: 2.18 | H5: 36.2 | J5: 0 | K5: 36.2 | M5: 0.458 | N5: 36.2 | P5: 7.147 | Q5: 36.2 | S5: 54.2 | T5: 36.2 | V5: 6.0622 | W5: 36.2 | Y5: 3 | Z5: 36.2 | AB5: 222 | AC5: 36.2 | AE5: 18.7 | AF5: 36.2 | AH5: 5.33 | AI5: 36.2
A6: 0.02985 | B6: 28.7 | D6: 0 | E6: 28.7 | G6: 2.18 | H6: 28.7 | J6: 0 | K6: 28.7 | M6: 0.458 | N6: 28.7 | P6: 6.43 | Q6: 28.7 | S6: 58.7 | T6: 28.7 | V6: 6.0622 | W6: 28.7 | Y6: 3 | Z6: 28.7 | AB6: 222 | AC6: 28.7 | AE6: 18.7 | AF6: 28.7 | AH6: 5.21 | AI6: 28.7
A7: 0.08829 | B7: 22.9 | D7: 12.5 | E7: 22.9 | G7: 7.87 | H7: 22.9 | J7: 0 | K7: 22.9 | M7: 0.524 | N7: 22.9 | P7: 6.012 | Q7: 22.9 | S7: 66.6 | T7: 22.9 | V7: 5.5605 | W7: 22.9 | Y7: 5 | Z7: 22.9 | AB7: 311 | AC7: 22.9 | AE7: 15.2 | AF7: 22.9 | AH7: 12.43 | AI7: 22.9
A8: 0.14455 | B8: 27.1 | D8: 12.5 | E8: 27.1 | G8: 7.87 | H8: 27.1 | J8: 0 | K8: 27.1 | M8: 0.524 | N8: 27.1 | P8: 6.172 | Q8: 27.1 | S8: 96.1 | T8: 27.1 | V8: 5.9505 | W8: 27.1 | Y8: 5 | Z8: 27.1 | AB8: 311 | AC8: 27.1 | AE8: 15.2 | AF8: 27.1 | AH8: 19.15 | AI8: 27.1
A9: 0.21124 | B9: 16.5 | D9: 12.5 | E9: 16.5 | G9: 7.87 | H9: 16.5 | J9: 0 | K9: 16.5 | M9: 0.524 | N9: 16.5 | P9: 5.631 | Q9: 16.5 | S9: 100 | T9: 16.5 | V9: 6.0821 | W9: 16.5 | Y9: 5 | Z9: 16.5 | AB9: 311 | AC9: 16.5 | AE9: 15.2 | AF9: 16.5 | AH9: 29.93 | AI9: 16.5
A10: 0.17004 | B10: 18.9 | D10: 12.5 | E10: 18.9 | G10: 7.87 | H10: 18.9 | J10: 0 | K10: 18.9 | M10: 0.524 | N10: 18.9 | P10: 6.004 | Q10: 18.9 | S10: 85.9 | T10: 18.9 | V10: 6.5921 | W10: 18.9 | Y10: 5 | Z10: 18.9 | AB10: 311 | AC10: 18.9 | AE10: 15.2 | AF10: 18.9 | AH10: 17.1 | AI10: 18.9
A11: 0.22489 | B11: 15 | D11: 12.5 | E11: 15 | G11: 7.87 | H11: 15 | J11: 0 | K11: 15 | M11: 0.524 | N11: 15 | P11: 6.377 | Q11: 15 | S11: 94.3 | T11: 15 | V11: 6.3467 | W11: 15 | Y11: 5 | Z11: 15 | AB11: 311 | AC11: 15 | AE11: 15.2 | AF11: 15 | AH11: 20.45 | AI11: 15
A12: 0.11747 | B12: 18.9 | D12: 12.5 | E12: 18.9 | G12: 7.87 | H12: 18.9 | J12: 0 | K12: 18.9 | M12: 0.524 | N12: 18.9 | P12: 6.009 | Q12: 18.9 | S12: 82.9 | T12: 18.9 | V12: 6.2267 | W12: 18.9 | Y12: 5 | Z12: 18.9 | AB12: 311 | AC12: 18.9 | AE12: 15.2 | AF12: 18.9 | AH12: 13.27 | AI12: 18.9
... A506: 0.04741 | B506: 11.9 | D506: 0 | E506: 11.9 | G506: 11.93 | H506: 11.9 | J506: 0 | K506: 11.9 | M506: 0.573 | N506: 11.9 | P506: 6.03 | Q506: 11.9 | S506: 80.8 | T506: 11.9 | V506: 2.505 | W506: 11.9 | Y506: 1 | Z506: 11.9 | AB506: 273 | AC506: 11.9 | AE506: 21 | AF506: 11.9 | AH506: 7.88 | AI506: 11.9

Sheet Distribution fitting_HID
A1: 0.00632 | B1: 0 | C1: 0.00632 | D1: 0
A2: 0.00632 | B2: 0.096650703 | C2: 0.00632 | D2: 0.096650703
A3: 0.05130494 | B3: 0.096650703 | C3: 9.003308 | D3: 0.096650703
A4: 0.05130494 | B4: 0 | C4: 9.003308 | D4: 0
A5: 0.09628988 | B5: 0 | C5: 9.003308 | D5: 0.0096650703
A6: 0.09628988 | B6: 0.096650703 | C6: 18.000296 | D6: 0.0096650703
A7: 0.14127482 | B7: 0.096650703 | C7: 18.000296 | D7: 0
A8: 0.14127482 | B8: 0 | C8: 18.000296 | D8: 0.002855589
A9: 0.18625976 | B9: 0 | C9: 26.997284 | D9: 0.002855589
A10: 0.18625976 | B10: 0.096650703 | C10: 26.997284 | D10: 0
A11: 0.2312447 | B11: 0.096650703 | C11: 26.997284 | D11: 0.00021966069
A12: 0.2312447 | B12: 0 | C12: 35.994272 | D12: 0.00021966069
... A31: 0.6810941 | B31: 0.096650703 | C31: 89.9762 | D31: 0
A32: 0.6810941 | B32: 0
A33: 0.72607904 | B33: 0
A34: 0.72607904 | B34: 0.096650703
A35: 0.77106398 | B35: 0.096650703
A36: 0.77106398 | B36: 0
A37: 0.81604892 | B37: 0
A38: 0.81604892 | B38: 0.096650703
A39: 0.86103386 | B39: 0.096650703
A40: 0.86103386 | B40: 0
A41: 0.9060188 | B41: 0
A42: 0.9060188 | B42: 0.096650703
A43: 0.95100374 | B43: 0.096650703
... A3620: 89.93166 | B3620: 0

Sheet Distribution fitting_HID1
A1: 2.9 | B1: 0 | C1: 2.9 | D1: 0
A2: 2.9 | B2: 0.0028203857 | C2: 2.9 | D2: 0.0028203857
A3: 2.94905 | B3: 0.0028203857 | C3: 12.71 | D3: 0.0028203857
A4: 2.94905 | B4: 0 | C4: 12.71 | D4: 0
A5: 2.9981 | B5: 0 | C5: 12.71 | D5: 0.0062451399
A6: 2.9981 | B6: 0.0028203857 | C6: 22.52 | D6: 0.0062451399
A7: 3.04715 | B7: 0.0028203857 | C7: 22.52 | D7: 0
A8: 3.04715 | B8: 0 | C8: 22.52 | D8: 0.0068495082
A9: 3.0962 | B9: 0 | C9: 32.33 | D9: 0.0068495082
A10: 3.0962 | B10: 0.0028203857 | C10: 32.33 | D10: 0
A11: 3.14525 | B11: 0.0028203857 | C11: 32.33 | D11: 0.0078567889
A12: 3.14525 | B12: 0 | C12: 42.14 | D12: 0.0078567889
... A31: 3.63575 | B31: 0.0028203857 | C31: 101 | D31: 0
A32: 3.63575 | B32: 0
A33: 3.6848 | B33: 0
A34: 3.6848 | B34: 0.0028203857
A35: 3.73385 | B35: 0.0028203857
A36: 3.73385 | B36: 0
A37: 3.7829 | B37: 0
A38: 3.7829 | B38: 0.0028203857
A39: 3.83195 | B39: 0.0028203857
A40: 3.83195 | B40: 0
A41: 3.881 | B41: 0
A42: 3.881 | B42: 0.0028203857
A43: 3.93005 | B43: 0.0028203857
... A4024: 100.95144 | B4024: 0

Sheet Distribution fitting_HID2
A1: -2.8276139 | B1: 0 | C1: -2.8276139 | D1: 0
A2: -2.8276139 | B2: 0.029375935 | C2: -2.8276139 | D2: 0.029375935
A3: -2.8245805 | B3: 0.029375935 | C3: -2.2148674 | D3: 0.029375935
A4: -2.8245805 | B4: 0 | C4: -2.2148674 | D4: 0
A5: -2.8215471 | B5: 0 | C5: -2.2148674 | D5: 0.065279855
A6: -2.8215471 | B6: 0.029375935 | C6: -1.602121 | D6: 0.065279855
A7: -2.8185137 | B7: 0.029375935 | C7: -1.602121 | D7: 0
A8: -2.8185137 | B8: 0 | C8: -1.602121 | D8: 0.16319964
A9: -2.8154803 | B9: 0 | C9: -0.98937452 | D9: 0.16319964
A10: -2.8154803 | B10: 0.029375935 | C10: -0.98937452 | D10: 0
A11: -2.8124469 | B11: 0.029375935 | C11: -0.98937452 | D11: 0.23827147
A12: -2.8124469 | B12: 0 | C12: -0.37662807 | D12: 0.23827147
... A31: -2.7821129 | B31: 0.029375935 | C31: 3.2998507 | D31: 0
A32: -2.7821129 | B32: 0
A33: -2.7790795 | B33: 0
A34: -2.7790795 | B34: 0.029375935
A35: -2.7760461 | B35: 0.029375935
A36: -2.7760461 | B36: 0
A37: -2.7730127 | B37: 0
A38: -2.7730127 | B38: 0.029375935
A39: -2.7699793 | B39: 0.029375935
A40: -2.7699793 | B40: 0
A41: -2.7669459 | B41: 0
A42: -2.7669459 | B42: 0.029375935
A43: -2.7639125 | B43: 0.029375935
... A4020: 3.2967869 | B4020: 0

Sheet Regression 1

Sheet Regression 2

Sheet Prediction
A1: IV Names | B1: Model Coefficients | C1: New Value
A2: Intercept
A3: CRIM | C3: 0.175
A4: ZN | C4: 0
A5: INDUS | C5: 10.6
A6: CHAS Coded | C6: 1
A7: NOX | C7: 0.5
A8: RM | C8: 6.5
A9: AGE | C9: 92.4
A10: DIS | C10: 3.94
A11: RAD | C11: 4
A12: TAX | C12: 275
A13: PTRATIO | C13: 18
A14: LSTAT | C14: 17.25
B15: Predicted MEDV

Sheet _PalUtilTempWorksheet
B9: =1 -> 1

Sheet _STDS_DG2B9C043C
A1: Name | B1: Boston Housing | C1: StatTools Version that generated sheet, Major | D1: 7 | E1: StatTools Version that generated sheet, Minor | F1: 6 | G1: StatTools Version that generated sheet, Revision | H1: 0 | I1: Min. StatTools Version to Read Sheet, Major (note ST versions before 1.1.1 don't perform forward compatibility check) | J1: 1 | K1: Min. StatTools Version to Read Sheet, Minor | L1: 0 | M1: Min. StatTools Version to Read Sheet, Revision | N1: 0 | O1: Min. StatTools version to not put up warning about extra info, Major | P1: 1 | Q1: Min. StatTools version to not put up warning about extra info, Minor | R1: 0 | S1: Min. StatTools version to not put up warning about extra info, Revision | T1: 0
A2: GUID | B2: DG2B9C043C
A3: Format Range | B3: =IF(B10>256,"TripUpST110AndEarlier",TRUE) -> TRUE
A4: Variable Layout | B4: Columns
A5: Variable Names In Cells | B5: TRUE
A6: Variable Names In 2nd Cells | B6: FALSE
A7: Data Set Ranges | B7: =Boston_Housing!$A$1:$N$507 -> No
A8: Data Sheet Format | B8: 2
A9: Formula Eval Cell | B9: =1 -> 1
A10: Num Stored Vars | B10: 15
A12: 1 : Info | B12: VG2EEDF21A835FEC | C12: var1 | D12: ST_RECORDID | E12: TRUE | F12: 0 | G12: 4 | H12: 0
A13: 1 : Ranges | B13: =Boston_Housing!$A$1:$A$507 -> 12
A14: 1 : MultiRefs
A15: 2 : Info | B15: VG2770A31F1526D850 | C15: var2 | D15: ST_MEDV | E15: TRUE | F15: 0 | G15: 4 | H15: 0
A16: 2 : Ranges | B16: =Boston_Housing!$O$1:$O$507 -> 18.2
A17: 2 : MultiRefs
A18: 3 : Info | B18: VG9B5A23133B797B4 | C18: var3 | D18: ST_CRIM | E18: TRUE | F18: 0 | G18: 4 | H18: 0
A19: 3 : Ranges | B19: =Boston_Housing!$D$1:$D$507 -> 0.7842
A20: 3 : MultiRefs
A21: 4 : Info | B21: VG2D5E4C5C21CD4E70 | C21: var4 | D21: ST_ZN | E21: TRUE | F21: 0 | G21: 4 | H21: 0
A22: 4 : Ranges | B22: =Boston_Housing!$E$1:$E$507 -> 0
A23: 4 : MultiRefs
A24: 5 : Info | B24: VG1732759219D1C56 | C24: var5 | D24: ST_INDUS | E24: TRUE | F24: 0 | G24: 4 | H24: 0
A25: 5 : Ranges | B25: =Boston_Housing!$F$1:$F$507 -> 8.14
A26: 5 : MultiRefs
A27: 6 : Info | B27: VG36348212249EFFE2 | C27: var6 | D27: ST_CHAS | E27: TRUE | F27: 0 | G27: 4 | H27: 1
A28: 6 : Ranges | B28: =Boston_Housing!$B$1:$B$507 -> No
A29: 6 : MultiRefs
A30: 7 : Info | B30: VG2F81C057882507C | C30: var7 | D30: ST_CHASCoded | E30: TRUE | F30: 0 | G30: 4 | H30: 0
A31: 7 : Ranges | B31: =Boston_Housing!#REF! -> #REF!
A32: 7 : MultiRefs
A33: 8 : Info | B33: VG28A301FDFAD4EE4 | C33: var8 | D33: ST_NOX | E33: TRUE | F33: 0 | G33: 4 | H33: 0
A34: 8 : Ranges | B34: =Boston_Housing!$G$1:$G$507 -> 0.538
A35: 8 : MultiRefs
A36: 9 : Info | B36: VG878FC572740E041 | C36: var9 | D36: ST_RM | E36: TRUE | F36: 0 | G36: 4 | H36: 0
A37: 9 : Ranges | B37: =Boston_Housing!$H$1:$H$507 -> 5.933
A38: 9 : MultiRefs
A39: 10 : Info | B39: VG33D62405383A2047 | C39: var10 | D39: ST_AGE | E39: TRUE | F39: 0 | G39: 4 | H39: 0
A40: 10 : Ranges | B40: =Boston_Housing!$I$1:$I$507 -> 30.2
A41: 10 : MultiRefs
...
